Workbook

Sheet Raw_Data
A1: SKU_ID | B1: Product_Name | C1: Category | D1: Warehouse | E1: Stock_Qty | F1: Unit_Price | G1: Reorder_Level | H1: Supplier | I1: Last_Restock_Date
A2: SKU1070 | B2: Bookshelf 3-Tier | C2: Furniture | D2: WH South | E2: 144 | F2: 2000.49 | G2: 12 | H2: Nova Wholesale | I2: 11/01/2025
A3: SKU1114 | B3: Track Pants | C3: APPAREL | D3: WH South | E3: 225 | G3: 28 | H3: Fine Goods Pvt Ltd | I3: 15-05-2025
A4: SKU1097 | B4: Sneakers Unisex | C4: footwear | D4: WH North | E4: 55 | F4: 2481.83 | G4: 40 | H4: Metro Distributors | I4: 09-01-2025
A5: SKU1158 | B5: Board Game | C5: Toys | D5: WH-South | E5: 140 | F5: 3079.49 | G5: 23 | H5: Nova Wholesale | I5: 13-06-2025
A6: SKU1058 | B6: Iron Box Steam | C6: HOME APPLIANCES | D6: wh-south | E6: 137 | F6: 3527.26 | G6: 32 | H6: Metro Distributors | I6: 23-05-2025
A7: SKU1001 | B7: LED Bulb 9W | C7: Electronics | D7: WH-North | E7: -5 | F7: 1017.32 | G7: 14 | H7: Prime Vendors | I7: 27-01-2025
A8: SKU1159 | B8: Board Game | C8: Toys | D8: WH-East | E8: 212 | F8: 338.24 | G8: 11 | H8: Global Supply Co | I8: 23/04/2025
A9: SKU1064 | B9: Plastic Chair | C9: Furniture | D9: WH-West | E9: 99 | G9: 37 | H9: Fine Goods Pvt Ltd | I9: 30-01-2025
A10: SKU1157 | B10: Board Game | C10: TOYS | D10: WH-North | E10: 83 | F10: 2516.69 | G10: 38 | H10: Nova Wholesale | I10: 28-03-2025
A11: SKU1037 | B11: Stapler Small | C11: Stationery | D11: Warehouse North | E11: 165 | F11: 542.27 | G11: 38 | H11: Metro Distributors | I11: 10/05/2025
A12: SKU1139 | B12: Cutlery Set | C12: Kitchenware | D12: WH-East | E12: 297 | F12: 2674.27 | G12: 12 | I12: 03-04-2025
A13: SKU1055 | B13: Room Heater 1000W | C13: home appliances | D13: WH-East | E13: -7 | F13: 3298.21 | G13: 13 | H13: Fine Goods Pvt Ltd | I13: 03-04-2025
A14: SKU1112 | B14: Formal Shirt | C14: APPAREL | D14: wh-west | E14: 276 | F14: 1708.34 | G14: 20 | H14: Global Supply Co | I14: 05/04/2025
A15: SKU1131 | B15: Pressure Cooker 3L | C15: Kitchenware | D15: WH-East | E15: 89 | F15: 222.59 | G15: 21 | H15: Prime Vendors | I15: 04-07-2025
A16: SKU1002 | B16: LED Bulb 9W | C16: Electronics | D16: WH-South | E16: 18 | F16: 2878.28 | G16: 32 | I16: 18-04-2025
A17: SKU1084 | B17: Running Shoes Men | C17: footwear | D17: WH-West | E17: 121 | G17: 13 | H17: Prime Vendors | I17: 30-06-2025
A18: SKU1102 | B18: Cotton T-Shirt | C18: APPAREL | D18: WH South | E18: 69 | F18: 2128.04 | G18: 33 | H18: Sharma Traders | I18: 02/05/2025
A19: SKU1038 | B19: Stapler Small | C19: Stationery | D19: WH South | E19: 220 | F19: 1547.62 | G19: 33 | I19: 07-06-2025
A20: SKU1108 | B20: Denim Jeans | C20: Apparel | D20: WH-West | E20: 67 | F20: 3500.75 | G20: 40 | H20: Fine Goods Pvt Ltd | I20: 11-08-2025
A21: SKU1011 | B21: Bluetooth Speaker | C21: electronics | D21: Warehouse East | E21: 179 | F21: 1767.32 | G21: 24 | H21: Sharma Traders | I21: 04-07-2025
A22: SKU1016 | B22: Power Bank 10000mAh | C22: electronics | D22: WH-West | E22: 39 | F22: 3445.56 | G22: 12 | H22: Nova Wholesale | I22: 02/03/2025
A23: SKU1071 | B23: Bookshelf 3-Tier | C23: furniture | D23: WH-East | E23: 299 | F23: 131.94 | G23: 34 | H23: Prime Vendors | I23: 30/07/2025
A24: SKU1106 | B24: Denim Jeans | C24: Apparel | D24: WH South | E24: 237 | F24: 2931.97 | G24: 20 | H24: Fine Goods Pvt Ltd | I24: 22-03-2025
A25: SKU1053 | B25: Room Heater 1000W | C25: Home Appliances | D25: WH North | E25: 63 | F25: 696.87 | G25: 19 | H25: Sharma Traders | I25: 29-05-2025
A26: SKU1099 | B26: Sneakers Unisex | C26: footwear | D26: Warehouse East | E26: 237 | F26: 887.82 | G26: 30 | H26: Nova Wholesale | I26: 06-01-2025
A27: SKU1081 | B27: Running Shoes Men | C27: FOOTWEAR | D27: Warehouse North | E27: 82 | F27: 196.23 | G27: 26 | H27: Nova Wholesale | I27: 26-03-2025
A28: SKU1060 | B28: Iron Box Steam | C28: Home Appliances | D28: wh-west | E28: 193 | F28: 2147.14 | G28: 23 | H28: Prime Vendors | I28: 21/05/2025
A29: SKU1109 | B29: Formal Shirt | C29: APPAREL | D29: WH North | E29: 113 | F29: 1954.65 | G29: 37 | H29: Sharma Traders | I29: 31-03-2025
A30: SKU1085 | B30: Sandals Women | C30: footwear | D30: wh-north | E30: 33 | F30: 1530.62 | G30: 14 | H30: Global Supply Co | I30: 16/05/2025
A31: SKU1008 | B31: USB Cable Type-C | C31: electronics | D31: wh-west | E31: 166 | F31: 2021.96 | G31: 38 | H31: Prime Vendors | I31: 28-04-2025
... A35: SKU1023 | B35: Gel Pen Blue | C35: STATIONERY | D35: WH-East | E35: 39 | F35: 979.06 | G35: 13 | H35: Nova Wholesale | I35: 05-03-2025
A36: SKU1136 | B36: Water Bottle 1L | C36: Kitchenware | D36: WH-West | E36: 176 | G36: 19 | H36: Fine Goods Pvt Ltd | I36: 28-06-2025
A37: SKU1151 | B37: Puzzle 100pc | C37: Toys | D37: WH-East | E37: 232 | F37: 3251.53 | G37: 40 | H37: Metro Distributors | I37: 20/06/2025
A38: SKU1080 | B38: Storage Rack | C38: Furniture | D38: WH-West | E38: 127 | F38: 972.57 | G38: 34 | H38: Fine Goods Pvt Ltd | I38: 12/01/2025
A39: SKU1146 | B39: Remote Car | C39: TOYS | D39: WH South | E39: 184 | F39: 2920.92 | G39: 39 | H39: Metro Distributors | I39: 07/06/2025
A40: SKU1088 | B40: Sandals Women | C40: FOOTWEAR | D40: wh-west | E40: 252 | F40: 1556.39 | G40: 21 | H40: Nova Wholesale | I40: 17-03-2025
A41: SKU1098 | B41: Sneakers Unisex | C41: Footwear | D41: WH-South | E41: 55 | F41: 1500.97 | G41: 38 | H41: Prime Vendors | I41: 02-04-2025
A42: SKU1148 | B42: Remote Car | C42: Toys | D42: wh-west | E42: 201 | F42: 177.92 | G42: 14 | H42: Prime Vendors | I42: 26/04/2025
A43: SKU1124 | B43: Non-Stick Pan | C43: kitchenware | D43: WH-West | E43: 248 | F43: 3833 | G43: 24 | H43: Sharma Traders | I43: 27/07/2025
...

Sheet Cleaned_Data
A1: SKU_ID | B1: Product_Name | C1: Category | D1: Warehouse | E1: Stock_Qty | F1: Stock_Corrected | G1: Unit_Price | H1: Reorder_Level | I1: Supplier | J1: Last_Restock_Date | K1: Duplicate_Status | L1: Stock_Status
A2: =Raw_Data!A2 -> SKU1070 | B2: =TRIM(PROPER(Raw_Data!B2)) -> Bookshelf 3-Tier | C2: =PROPER(TRIM(Raw_Data!C2)) -> Furniture | D2: =IF(ISNUMBER(SEARCH("north",Raw_Data!D2)),"WH-North",IF(ISNUMBER(SEARCH("south",Raw_Data!D2)),"WH-South",IF(ISNUMBER(SEARCH("east",Raw_Data!D2)),"WH-East",IF(ISNUMBER(SEARCH("west",Raw_Data!D2)),"WH-West","Unknown")))) -> WH-South | E2: =IF(Raw_Data!E2<0,0,Raw_Data!E2) -> 144 | F2: =IF(Raw_Data!E2<0,"Yes","No") -> No | G2: =IF(Raw_Data!F2="",ROUND(AVERAGEIFS(Raw_Data!$F$2:$F$176,$C$2:$C$176,C2),2),Raw_Data!F2) -> 2000.49 | H2: =Raw_Data!G2 -> 12 | I2: =IF(TRIM(Raw_Data!H2)="","Not Assigned",TRIM(Raw_Data!H2)) -> Nova Wholesale | J2: =DATE(VALUE(MID(SUBSTITUTE(Raw_Data!I2,"/","-"),7,4)),VALUE(MID(SUBSTITUTE(Raw_Data!I2,"/","-"),4,2)),VALUE(LEFT(SUBSTITUTE(Raw_Data!I2,"/","-"),2))) -> 45668 | K2: =IF(COUNTIF(Raw_Data!$A$2:A2,Raw_Data!A2)>1,"Duplicate - Remove","Keep") -> Keep | L2: =IF(E2<H2,"Reorder Needed","OK") -> OK
A3: =Raw_Data!A3 -> SKU1114 | B3: =TRIM(PROPER(Raw_Data!B3)) -> Track Pants | C3: =PROPER(TRIM(Raw_Data!C3)) -> Apparel | D3: =IF(ISNUMBER(SEARCH("north",Raw_Data!D3)),"WH-North",IF(ISNUMBER(SEARCH("south",Raw_Data!D3)),"WH-South",IF(ISNUMBER(SEARCH("east",Raw_Data!D3)),"WH-East",IF(ISNUMBER(SEARCH("west",Raw_Data!D3)),"WH-West","Unknown")))) -> WH-South | E3: =IF(Raw_Data!E3<0,0,Raw_Data!E3) -> 225 | F3: =IF(Raw_Data!E3<0,"Yes","No") -> No | G3: =IF(Raw_Data!F3="",ROUND(AVERAGEIFS(Raw_Data!$F$2:$F$176,$C$2:$C$176,C3),2),Raw_Data!F3) -> 1910.3 | H3: =Raw_Data!G3 -> 28 | I3: =IF(TRIM(Raw_Data!H3)="","Not Assigned",TRIM(Raw_Data!H3)) -> Fine Goods Pvt Ltd | J3: =DATE(VALUE(MID(SUBSTITUTE(Raw_Data!I3,"/","-"),7,4)),VALUE(MID(SUBSTITUTE(Raw_Data!I3,"/","-"),4,2)),VALUE(LEFT(SUBSTITUTE(Raw_Data!I3,"/","-"),2))) -> 45792 | K3: =IF(COUNTIF(Raw_Data!$A$2:A3,Raw_Data!A3)>1,"Duplicate - Remove","Keep") -> Keep | L3: =IF(E3<H3,"Reorder Needed","OK") -> OK
A4: =Raw_Data!A4 -> SKU1097 | B4: =TRIM(PROPER(Raw_Data!B4)) -> Sneakers Unisex | C4: =PROPER(TRIM(Raw_Data!C4)) -> Footwear | D4: =IF(ISNUMBER(SEARCH("north",Raw_Data!D4)),"WH-North",IF(ISNUMBER(SEARCH("south",Raw_Data!D4)),"WH-South",IF(ISNUMBER(SEARCH("east",Raw_Data!D4)),"WH-East",IF(ISNUMBER(SEARCH("west",Raw_Data!D4)),"WH-West","Unknown")))) -> WH-North | E4: =IF(Raw_Data!E4<0,0,Raw_Data!E4) -> 55 | F4: =IF(Raw_Data!E4<0,"Yes","No") -> No | G4: =IF(Raw_Data!F4="",ROUND(AVERAGEIFS(Raw_Data!$F$2:$F$176,$C$2:$C$176,C4),2),Raw_Data!F4) -> 2481.83 | H4: =Raw_Data!G4 -> 40 | I4: =IF(TRIM(Raw_Data!H4)="","Not Assigned",TRIM(Raw_Data!H4)) -> Metro Distributors | J4: =DATE(VALUE(MID(SUBSTITUTE(Raw_Data!I4,"/","-"),7,4)),VALUE(MID(SUBSTITUTE(Raw_Data!I4,"/","-"),4,2)),VALUE(LEFT(SUBSTITUTE(Raw_Data!I4,"/","-"),2))) -> 45666 | K4: =IF(COUNTIF(Raw_Data!$A$2:A4,Raw_Data!A4)>1,"Duplicate - Remove","Keep") -> Keep | L4: =IF(E4<H4,"Reorder Needed","OK") -> OK
A5: =Raw_Data!A5 -> SKU1158 | B5: =TRIM(PROPER(Raw_Data!B5)) -> Board Game | C5: =PROPER(TRIM(Raw_Data!C5)) -> Toys | D5: =IF(ISNUMBER(SEARCH("north",Raw_Data!D5)),"WH-North",IF(ISNUMBER(SEARCH("south",Raw_Data!D5)),"WH-South",IF(ISNUMBER(SEARCH("east",Raw_Data!D5)),"WH-East",IF(ISNUMBER(SEARCH("west",Raw_Data!D5)),"WH-West","Unknown")))) -> WH-South | E5: =IF(Raw_Data!E5<0,0,Raw_Data!E5) -> 140 | F5: =IF(Raw_Data!E5<0,"Yes","No") -> No | G5: =IF(Raw_Data!F5="",ROUND(AVERAGEIFS(Raw_Data!$F$2:$F$176,$C$2:$C$176,C5),2),Raw_Data!F5) -> 3079.49 | H5: =Raw_Data!G5 -> 23 | I5: =IF(TRIM(Raw_Data!H5)="","Not Assigned",TRIM(Raw_Data!H5)) -> Nova Wholesale | J5: =DATE(VALUE(MID(SUBSTITUTE(Raw_Data!I5,"/","-"),7,4)),VALUE(MID(SUBSTITUTE(Raw_Data!I5,"/","-"),4,2)),VALUE(LEFT(SUBSTITUTE(Raw_Data!I5,"/","-"),2))) -> 45821 | K5: =IF(COUNTIF(Raw_Data!$A$2:A5,Raw_Data!A5)>1,"Duplicate - Remove","Keep") -> Keep | L5: =IF(E5<H5,"Reorder Needed","OK") -> OK
A6: =Raw_Data!A6 -> SKU1058 | B6: =TRIM(PROPER(Raw_Data!B6)) -> Iron Box Steam | C6: =PROPER(TRIM(Raw_Data!C6)) -> Home Appliances | D6: =IF(ISNUMBER(SEARCH("north",Raw_Data!D6)),"WH-North",IF(ISNUMBER(SEARCH("south",Raw_Data!D6)),"WH-South",IF(ISNUMBER(SEARCH("east",Raw_Data!D6)),"WH-East",IF(ISNUMBER(SEARCH("west",Raw_Data!D6)),"WH-West","Unknown")))) -> WH-South | E6: =IF(Raw_Data!E6<0,0,Raw_Data!E6) -> 137 | F6: =IF(Raw_Data!E6<0,"Yes","No") -> No | G6: =IF(Raw_Data!F6="",ROUND(AVERAGEIFS(Raw_Data!$F$2:$F$176,$C$2:$C$176,C6),2),Raw_Data!F6) -> 3527.26 | H6: =Raw_Data!G6 -> 32 | I6: =IF(TRIM(Raw_Data!H6)="","Not Assigned",TRIM(Raw_Data!H6)) -> Metro Distributors | J6: =DATE(VALUE(MID(SUBSTITUTE(Raw_Data!I6,"/","-"),7,4)),VALUE(MID(SUBSTITUTE(Raw_Data!I6,"/","-"),4,2)),VALUE(LEFT(SUBSTITUTE(Raw_Data!I6,"/","-"),2))) -> 45800 | K6: =IF(COUNTIF(Raw_Data!$A$2:A6,Raw_Data!A6)>1,"Duplicate - Remove","Keep") -> Keep | L6: =IF(E6<H6,"Reorder Needed","OK") -> OK
A7: =Raw_Data!A7 -> SKU1001 | B7: =TRIM(PROPER(Raw_Data!B7)) -> Led Bulb 9W | C7: =PROPER(TRIM(Raw_Data!C7)) -> Electronics | D7: =IF(ISNUMBER(SEARCH("north",Raw_Data!D7)),"WH-North",IF(ISNUMBER(SEARCH("south",Raw_Data!D7)),"WH-South",IF(ISNUMBER(SEARCH("east",Raw_Data!D7)),"WH-East",IF(ISNUMBER(SEARCH("west",Raw_Data!D7)),"WH-West","Unknown")))) -> WH-North | E7: =IF(Raw_Data!E7<0,0,Raw_Data!E7) -> 0 | F7: =IF(Raw_Data!E7<0,"Yes","No") -> Yes | G7: =IF(Raw_Data!F7="",ROUND(AVERAGEIFS(Raw_Data!$F$2:$F$176,$C$2:$C$176,C7),2),Raw_Data!F7) -> 1017.32 | H7: =Raw_Data!G7 -> 14 | I7: =IF(TRIM(Raw_Data!H7)="","Not Assigned",TRIM(Raw_Data!H7)) -> Prime Vendors | J7: =DATE(VALUE(MID(SUBSTITUTE(Raw_Data!I7,"/","-"),7,4)),VALUE(MID(SUBSTITUTE(Raw_Data!I7,"/","-"),4,2)),VALUE(LEFT(SUBSTITUTE(Raw_Data!I7,"/","-"),2))) -> 45684 | K7: =IF(COUNTIF(Raw_Data!$A$2:A7,Raw_Data!A7)>1,"Duplicate - Remove","Keep") -> Keep | L7: =IF(E7<H7,"Reorder Needed","OK") -> Reorder Needed
A8: =Raw_Data!A8 -> SKU1159 | B8: =TRIM(PROPER(Raw_Data!B8)) -> Board Game | C8: =PROPER(TRIM(Raw_Data!C8)) -> Toys | D8: =IF(ISNUMBER(SEARCH("north",Raw_Data!D8)),"WH-North",IF(ISNUMBER(SEARCH("south",Raw_Data!D8)),"WH-South",IF(ISNUMBER(SEARCH("east",Raw_Data!D8)),"WH-East",IF(ISNUMBER(SEARCH("west",Raw_Data!D8)),"WH-West","Unknown")))) -> WH-East | E8: =IF(Raw_Data!E8<0,0,Raw_Data!E8) -> 212 | F8: =IF(Raw_Data!E8<0,"Yes","No") -> No | G8: =IF(Raw_Data!F8="",ROUND(AVERAGEIFS(Raw_Data!$F$2:$F$176,$C$2:$C$176,C8),2),Raw_Data!F8) -> 338.24 | H8: =Raw_Data!G8 -> 11 | I8: =IF(TRIM(Raw_Data!H8)="","Not Assigned",TRIM(Raw_Data!H8)) -> Global Supply Co | J8: =DATE(VALUE(MID(SUBSTITUTE(Raw_Data!I8,"/","-"),7,4)),VALUE(MID(SUBSTITUTE(Raw_Data!I8,"/","-"),4,2)),VALUE(LEFT(SUBSTITUTE(Raw_Data!I8,"/","-"),2))) -> 45770 | K8: =IF(COUNTIF(Raw_Data!$A$2:A8,Raw_Data!A8)>1,"Duplicate - Remove","Keep") -> Keep | L8: =IF(E8<H8,"Reorder Needed","OK") -> OK
A9: =Raw_Data!A9 -> SKU1064 | B9: =TRIM(PROPER(Raw_Data!B9)) -> Plastic Chair | C9: =PROPER(TRIM(Raw_Data!C9)) -> Furniture | D9: =IF(ISNUMBER(SEARCH("north",Raw_Data!D9)),"WH-North",IF(ISNUMBER(SEARCH("south",Raw_Data!D9)),"WH-South",IF(ISNUMBER(SEARCH("east",Raw_Data!D9)),"WH-East",IF(ISNUMBER(SEARCH("west",Raw_Data!D9)),"WH-West","Unknown")))) -> WH-West | E9: =IF(Raw_Data!E9<0,0,Raw_Data!E9) -> 99 | F9: =IF(Raw_Data!E9<0,"Yes","No") -> No | G9: =IF(Raw_Data!F9="",ROUND(AVERAGEIFS(Raw_Data!$F$2:$F$176,$C$2:$C$176,C9),2),Raw_Data!F9) -> 1780.89 | H9: =Raw_Data!G9 -> 37 | I9: =IF(TRIM(Raw_Data!H9)="","Not Assigned",TRIM(Raw_Data!H9)) -> Fine Goods Pvt Ltd | J9: =DATE(VALUE(MID(SUBSTITUTE(Raw_Data!I9,"/","-"),7,4)),VALUE(MID(SUBSTITUTE(Raw_Data!I9,"/","-"),4,2)),VALUE(LEFT(SUBSTITUTE(Raw_Data!I9,"/","-"),2))) -> 45687 | K9: =IF(COUNTIF(Raw_Data!$A$2:A9,Raw_Data!A9)>1,"Duplicate - Remove","Keep") -> Keep | L9: =IF(E9<H9,"Reorder Needed","OK") -> OK
A10: =Raw_Data!A10 -> SKU1157 | B10: =TRIM(PROPER(Raw_Data!B10)) -> Board Game | C10: =PROPER(TRIM(Raw_Data!C10)) -> Toys | D10: =IF(ISNUMBER(SEARCH("north",Raw_Data!D10)),"WH-North",IF(ISNUMBER(SEARCH("south",Raw_Data!D10)),"WH-South",IF(ISNUMBER(SEARCH("east",Raw_Data!D10)),"WH-East",IF(ISNUMBER(SEARCH("west",Raw_Data!D10)),"WH-West","Unknown")))) -> WH-North | E10: =IF(Raw_Data!E10<0,0,Raw_Data!E10) -> 83 | F10: =IF(Raw_Data!E10<0,"Yes","No") -> No | G10: =IF(Raw_Data!F10="",ROUND(AVERAGEIFS(Raw_Data!$F$2:$F$176,$C$2:$C$176,C10),2),Raw_Data!F10) -> 2516.69 | H10: =Raw_Data!G10 -> 38 | I10: =IF(TRIM(Raw_Data!H10)="","Not Assigned",TRIM(Raw_Data!H10)) -> Nova Wholesale | J10: =DATE(VALUE(MID(SUBSTITUTE(Raw_Data!I10,"/","-"),7,4)),VALUE(MID(SUBSTITUTE(Raw_Data!I10,"/","-"),4,2)),VALUE(LEFT(SUBSTITUTE(Raw_Data!I10,"/","-"),2))) -> 45744 | K10: =IF(COUNTIF(Raw_Data!$A$2:A10,Raw_Data!A10)>1,"Duplicate - Remove","Keep") -> Keep | L10: =IF(E10<H10,"Reorder Needed","OK") -> OK
A11: =Raw_Data!A11 -> SKU1037 | B11: =TRIM(PROPER(Raw_Data!B11)) -> Stapler Small | C11: =PROPER(TRIM(Raw_Data!C11)) -> Stationery | D11: =IF(ISNUMBER(SEARCH("north",Raw_Data!D11)),"WH-North",IF(ISNUMBER(SEARCH("south",Raw_Data!D11)),"WH-South",IF(ISNUMBER(SEARCH("east",Raw_Data!D11)),"WH-East",IF(ISNUMBER(SEARCH("west",Raw_Data!D11)),"WH-West","Unknown")))) -> WH-North | E11: =IF(Raw_Data!E11<0,0,Raw_Data!E11) -> 165 | F11: =IF(Raw_Data!E11<0,"Yes","No") -> No | G11: =IF(Raw_Data!F11="",ROUND(AVERAGEIFS(Raw_Data!$F$2:$F$176,$C$2:$C$176,C11),2),Raw_Data!F11) -> 542.27 | H11: =Raw_Data!G11 -> 38 | I11: =IF(TRIM(Raw_Data!H11)="","Not Assigned",TRIM(Raw_Data!H11)) -> Metro Distributors | J11: =DATE(VALUE(MID(SUBSTITUTE(Raw_Data!I11,"/","-"),7,4)),VALUE(MID(SUBSTITUTE(Raw_Data!I11,"/","-"),4,2)),VALUE(LEFT(SUBSTITUTE(Raw_Data!I11,"/","-"),2))) -> 45787 | K11: =IF(COUNTIF(Raw_Data!$A$2:A11,Raw_Data!A11)>1,"Duplicate - Remove","Keep") -> Keep | L11: =IF(E11<H11,"Reorder Needed","OK") -> OK
A12: =Raw_Data!A12 -> SKU1139 | B12: =TRIM(PROPER(Raw_Data!B12)) -> Cutlery Set | C12: =PROPER(TRIM(Raw_Data!C12)) -> Kitchenware | D12: =IF(ISNUMBER(SEARCH("north",Raw_Data!D12)),"WH-North",IF(ISNUMBER(SEARCH("south",Raw_Data!D12)),"WH-South",IF(ISNUMBER(SEARCH("east",Raw_Data!D12)),"WH-East",IF(ISNUMBER(SEARCH("west",Raw_Data!D12)),"WH-West","Unknown")))) -> WH-East | E12: =IF(Raw_Data!E12<0,0,Raw_Data!E12) -> 297 | F12: =IF(Raw_Data!E12<0,"Yes","No") -> No | G12: =IF(Raw_Data!F12="",ROUND(AVERAGEIFS(Raw_Data!$F$2:$F$176,$C$2:$C$176,C12),2),Raw_Data!F12) -> 2674.27 | H12: =Raw_Data!G12 -> 12 | I12: =IF(TRIM(Raw_Data!H12)="","Not Assigned",TRIM(Raw_Data!H12)) -> Not Assigned | J12: =DATE(VALUE(MID(SUBSTITUTE(Raw_Data!I12,"/","-"),7,4)),VALUE(MID(SUBSTITUTE(Raw_Data!I12,"/","-"),4,2)),VALUE(LEFT(SUBSTITUTE(Raw_Data!I12,"/","-"),2))) -> 45750 | K12: =IF(COUNTIF(Raw_Data!$A$2:A12,Raw_Data!A12)>1,"Duplicate - Remove","Keep") -> Keep | L12: =IF(E12<H12,"Reorder Needed","OK") -> OK
A13: =Raw_Data!A13 -> SKU1055 | B13: =TRIM(PROPER(Raw_Data!B13)) -> Room Heater 1000W | C13: =PROPER(TRIM(Raw_Data!C13)) -> Home Appliances | D13: =IF(ISNUMBER(SEARCH("north",Raw_Data!D13)),"WH-North",IF(ISNUMBER(SEARCH("south",Raw_Data!D13)),"WH-South",IF(ISNUMBER(SEARCH("east",Raw_Data!D13)),"WH-East",IF(ISNUMBER(SEARCH("west",Raw_Data!D13)),"WH-West","Unknown")))) -> WH-East | E13: =IF(Raw_Data!E13<0,0,Raw_Data!E13) -> 0 | F13: =IF(Raw_Data!E13<0,"Yes","No") -> Yes | G13: =IF(Raw_Data!F13="",ROUND(AVERAGEIFS(Raw_Data!$F$2:$F$176,$C$2:$C$176,C13),2),Raw_Data!F13) -> 3298.21 | H13: =Raw_Data!G13 -> 13 | I13: =IF(TRIM(Raw_Data!H13)="","Not Assigned",TRIM(Raw_Data!H13)) -> Fine Goods Pvt Ltd | J13: =DATE(VALUE(MID(SUBSTITUTE(Raw_Data!I13,"/","-"),7,4)),VALUE(MID(SUBSTITUTE(Raw_Data!I13,"/","-"),4,2)),VALUE(LEFT(SUBSTITUTE(Raw_Data!I13,"/","-"),2))) -> 45750 | K13: =IF(COUNTIF(Raw_Data!$A$2:A13,Raw_Data!A13)>1,"Duplicate - Remove","Keep") -> Keep | L13: =IF(E13<H13,"Reorder Needed","OK") -> Reorder Needed
... A176: =Raw_Data!A176 -> SKU1120 | B176: =TRIM(PROPER(Raw_Data!B176)) -> Winter Jacket | C176: =PROPER(TRIM(Raw_Data!C176)) -> Apparel | D176: =IF(ISNUMBER(SEARCH("north",Raw_Data!D176)),"WH-North",IF(ISNUMBER(SEARCH("south",Raw_Data!D176)),"WH-South",IF(ISNUMBER(SEARCH("east",Raw_Data!D176)),"WH-East",IF(ISNUMBER(SEARCH("west",Raw_Data!D176)),"WH-West","Unknown")))) -> WH-West | E176: =IF(Raw_Data!E176<0,0,Raw_Data!E176) -> 80 | F176: =IF(Raw_Data!E176<0,"Yes","No") -> No | G176: =IF(Raw_Data!F176="",ROUND(AVERAGEIFS(Raw_Data!$F$2:$F$176,$C$2:$C$176,C176),2),Raw_Data!F176) -> 628.45 | H176: =Raw_Data!G176 -> 16 | I176: =IF(TRIM(Raw_Data!H176)="","Not Assigned",TRIM(Raw_Data!H176)) -> Global Supply Co | J176: =DATE(VALUE(MID(SUBSTITUTE(Raw_Data!I176,"/","-"),7,4)),VALUE(MID(SUBSTITUTE(Raw_Data!I176,"/","-"),4,2)),VALUE(LEFT(SUBSTITUTE(Raw_Data!I176,"/","-"),2))) -> 45812 | K176: =IF(COUNTIF(Raw_Data!$A$2:A176,Raw_Data!A176)>1,"Duplicate - Remove","Keep") -> Keep | L176: =IF(E176<H176,"Reorder Needed","OK") -> OK

Sheet Cleaning_Log
A1: Issue Found | B1: How It Was Fixed (formula logic)
A2: Extra spaces in Product_Name | B2: TRIM() removes leading/trailing spaces; PROPER() fixes casing so the same product always reads the same way.
A3: Category typed in different cases | B3: PROPER(TRIM()) normalizes 'ELECTRONICS' / 'electronics' / 'Electronics' to one consistent 'Electronics'.
A4: Warehouse name has 4+ spellings | B4: SEARCH() checks for the keyword (north/south/east/west) anywhere in the text, case-insensitive, and maps it to a standard code (WH-North etc.), regardless of how it was typed.
A5: Negative Stock_Qty (return-processing bug) | B5: Any negative value is reset to 0 with IF(...<0,0,...). A separate Stock_Corrected flag keeps a record of which rows were touched, instead of silently overwriting the issue.
A6: Missing Unit_Price on some SKUs | B6: Where price is blank, AVERAGEIFS() fills it with the average price of other SKUs in the same (cleaned) category, rather than leaving a blank that would break later SUM/AVG calculations.
A7: Missing Supplier on some SKUs | B7: Blank supplier is replaced with 'Not Assigned' so the field is never empty (empty text breaks GROUP BY / pivot counts downstream).
A8: Last_Restock_Date mixed dd-mm-yyyy and dd/mm/yyyy | B8: SUBSTITUTE() converts every '/' to '-' first so both formats line up the same way, then LEFT/MID/VALUE pull out day, month and year to rebuild a real Excel date with DATE().
A9: 15 duplicate rows from double barcode scans | B9: COUNTIF() over a growing range flags the first time a SKU is seen as 'Keep' and every repeat as 'Duplicate - Remove', so duplicates can be filtered out before the SQL load.
A10: No visibility into which SKUs need reordering | B10: Added a Stock_Status column comparing cleaned Stock_Qty to Reorder_Level — this becomes the seed for the Power BI reorder-alert visual.
